Process CallAgentListener-1:
Traceback (most recent call last):
  File "/home/xh/anaconda3/envs/platform/lib/python3.7/multiprocessing/process.py", line 297, in _bootstrap
    self.run()
  File "/home/xh/code/texas_poker/server/agent/callagent.py", line 18, in run
    server.bind((cfg["bot"]["CallAgent"]["host"], cfg["bot"]["CallAgent"]["port"]))
OSError: [Errno 98] Address already in use
 [*] Waiting for messages. To exit press CTRL+C
2020-05-20 18:47:46.031 | INFO | /home/xh/code/texas_poker/server/network/protocols.py:28 | MainProcess | - recv client from 127.0.0.1, 40402: {'info': 'ai_vs_ai', 'room_id': 0, 'room_number': 2, 'bots': ['CallAgent', 'CallAgent'], 'game_number': 2}
2020-05-20 18:47:46.033 | INFO | /home/xh/code/texas_poker/server/network/protocols.py:28 | MainProcess | - recv client from 127.0.0.1, 40404: {'info': 'ai_vs_ai', 'room_id': 1, 'room_number': 2, 'bots': ['CallAgent', 'CallAgent'], 'game_number': 2}
 [*] Waiting for messages. To exit press CTRL+C
2020-05-20 18:47:46.033 | INFO | /home/xh/code/texas_poker/server/network/scheduler.py:38 | MainProcess | - recv connect message {'info': 'ai_vs_ai', 'room_id': 0, 'room_number': 2, 'bots': ['CallAgent', 'CallAgent'], 'game_number': 2, 'uuid': '1236f82b-53a6-442f-ba52-2e25a11397bc'}
2020-05-20 18:47:46.034 | ERROR | /home/xh/code/texas_poker/server/network/scheduler.py:49 | MainProcess | - [Errno 111] Connection refused
Traceback (most recent call last):

  File "init/init_scheduler.py", line 4, in <module>
    Scheduler().start()
    └ <class 'network.scheduler.Scheduler'>

  File "/home/xh/code/texas_poker/server/network/scheduler.py", line 109, in start
    self.channel.start_consuming()
    │    │       └ <function BlockingChannel.start_consuming at 0x7f649952bc20>
    │    └ <BlockingChannel impl=<Channel number=1 OPEN conn=<SelectConnection OPEN transport=<pika.adapters.utils.io_services_utils._As...
    └ <network.scheduler.Scheduler object at 0x7f649b78e410>

  File "/home/xh/anaconda3/envs/platform/lib/python3.7/site-packages/pika/adapters/blocking_connection.py", line 1866, in start_consuming
    self._process_data_events(time_limit=None)
    │    └ <function BlockingChannel._process_data_events at 0x7f649952bdd0>
    └ <BlockingChannel impl=<Channel number=1 OPEN conn=<SelectConnection OPEN transport=<pika.adapters.utils.io_services_utils._As...
  File "/home/xh/anaconda3/envs/platform/lib/python3.7/site-packages/pika/adapters/blocking_connection.py", line 2027, in _process_data_events
    self.connection.process_data_events(time_limit=time_limit)
    │    │                                         └ None
    │    └ <property object at 0x7f6499526d70>
    └ <BlockingChannel impl=<Channel number=1 OPEN conn=<SelectConnection OPEN transport=<pika.adapters.utils.io_services_utils._As...
  File "/home/xh/anaconda3/envs/platform/lib/python3.7/site-packages/pika/adapters/blocking_connection.py", line 834, in process_data_events
    self._dispatch_channel_events()
    │    └ <function BlockingConnection._dispatch_channel_events at 0x7f64995234d0>
    └ <BlockingConnection impl=<SelectConnection OPEN transport=<pika.adapters.utils.io_services_utils._AsyncPlaintextTransport obj...
  File "/home/xh/anaconda3/envs/platform/lib/python3.7/site-packages/pika/adapters/blocking_connection.py", line 566, in _dispatch_channel_events
    impl_channel._get_cookie()._dispatch_events()
    │            └ <function Channel._get_cookie at 0x7f64995aec20>
    └ <Channel number=1 OPEN conn=<SelectConnection OPEN transport=<pika.adapters.utils.io_services_utils._AsyncPlaintextTransport ...
  File "/home/xh/anaconda3/envs/platform/lib/python3.7/site-packages/pika/adapters/blocking_connection.py", line 1494, in _dispatch_events
    evt.properties, evt.body)
    │   │           │   └ <member 'body' of '_ConsumerDeliveryEvt' objects>
    │   │           └ <pika.adapters.blocking_connection._ConsumerDeliveryEvt object at 0x7f6498f66d70>
    │   └ <member 'properties' of '_ConsumerDeliveryEvt' objects>
    └ <pika.adapters.blocking_connection._ConsumerDeliveryEvt object at 0x7f6498f66d70>

> File "/home/xh/code/texas_poker/server/network/scheduler.py", line 43, in callback
    self.handle_ai_vs_ai(data)
    │    │               └ {'info': 'ai_vs_ai', 'room_id': 0, 'room_number': 2, 'bots': ['CallAgent', 'CallAgent'], 'game_number': 2, 'uuid': '1236f82b-...
    │    └ <function Scheduler.handle_ai_vs_ai at 0x7f64995405f0>
    └ <network.scheduler.Scheduler object at 0x7f649b78e410>

  File "/home/xh/code/texas_poker/server/network/scheduler.py", line 64, in handle_ai_vs_ai
    self.notify_bots(room, bots)
    │    │           │     └ ['CallAgent', 'CallAgent']
    │    │           └ {'room_id': 0, 'room_number': 2, 'game_number': 2, 'uuid': [], 'name': [], 'notify_bot': False}
    │    └ <function Scheduler.notify_bots at 0x7f6498f42a70>
    └ <network.scheduler.Scheduler object at 0x7f649b78e410>

  File "/home/xh/code/texas_poker/server/network/scheduler.py", line 97, in notify_bots
    client.connect((cfg["bot"][bot]["host"], cfg["bot"][bot]["port"]))
    │      │        │          │             │          └ 'CallAgent'
    │      │        │          │             └ {'server': {'host': '127.0.0.1', 'port': 12345}, 'bot': {'RandomAgent': {'host': '127.0.0.1', 'port': 20001}, 'CallAgent': {'...
    │      │        │          └ 'CallAgent'
    │      │        └ {'server': {'host': '127.0.0.1', 'port': 12345}, 'bot': {'RandomAgent': {'host': '127.0.0.1', 'port': 20001}, 'CallAgent': {'...
    │      └ <method 'connect' of '_socket.socket' objects>
    └ <socket.socket fd=9, family=AddressFamily.AF_INET, type=SocketKind.SOCK_STREAM, proto=0, laddr=('0.0.0.0', 52776)>

ConnectionRefusedError: [Errno 111] Connection refused
2020-05-20 18:47:46.045 | INFO | /home/xh/code/texas_poker/server/network/scheduler.py:38 | MainProcess | - recv connect message {'info': 'ai_vs_ai', 'room_id': 1, 'room_number': 2, 'bots': ['CallAgent', 'CallAgent'], 'game_number': 2, 'uuid': '9854b2b9-710b-4fe0-8fbd-5fabe395740f'}
2020-05-20 18:47:46.045 | ERROR | /home/xh/code/texas_poker/server/network/scheduler.py:49 | MainProcess | - [Errno 111] Connection refused
Traceback (most recent call last):

  File "init/init_scheduler.py", line 4, in <module>
    Scheduler().start()
    └ <class 'network.scheduler.Scheduler'>

  File "/home/xh/code/texas_poker/server/network/scheduler.py", line 109, in start
    self.channel.start_consuming()
    │    │       └ <function BlockingChannel.start_consuming at 0x7f649952bc20>
    │    └ <BlockingChannel impl=<Channel number=1 OPEN conn=<SelectConnection OPEN transport=<pika.adapters.utils.io_services_utils._As...
    └ <network.scheduler.Scheduler object at 0x7f649b78e410>

  File "/home/xh/anaconda3/envs/platform/lib/python3.7/site-packages/pika/adapters/blocking_connection.py", line 1866, in start_consuming
    self._process_data_events(time_limit=None)
    │    └ <function BlockingChannel._process_data_events at 0x7f649952bdd0>
    └ <BlockingChannel impl=<Channel number=1 OPEN conn=<SelectConnection OPEN transport=<pika.adapters.utils.io_services_utils._As...
  File "/home/xh/anaconda3/envs/platform/lib/python3.7/site-packages/pika/adapters/blocking_connection.py", line 2027, in _process_data_events
    self.connection.process_data_events(time_limit=time_limit)
    │    │                                         └ None
    │    └ <property object at 0x7f6499526d70>
    └ <BlockingChannel impl=<Channel number=1 OPEN conn=<SelectConnection OPEN transport=<pika.adapters.utils.io_services_utils._As...
  File "/home/xh/anaconda3/envs/platform/lib/python3.7/site-packages/pika/adapters/blocking_connection.py", line 834, in process_data_events
    self._dispatch_channel_events()
    │    └ <function BlockingConnection._dispatch_channel_events at 0x7f64995234d0>
    └ <BlockingConnection impl=<SelectConnection OPEN transport=<pika.adapters.utils.io_services_utils._AsyncPlaintextTransport obj...
  File "/home/xh/anaconda3/envs/platform/lib/python3.7/site-packages/pika/adapters/blocking_connection.py", line 566, in _dispatch_channel_events
    impl_channel._get_cookie()._dispatch_events()
    │            └ <function Channel._get_cookie at 0x7f64995aec20>
    └ <Channel number=1 OPEN conn=<SelectConnection OPEN transport=<pika.adapters.utils.io_services_utils._AsyncPlaintextTransport ...
  File "/home/xh/anaconda3/envs/platform/lib/python3.7/site-packages/pika/adapters/blocking_connection.py", line 1494, in _dispatch_events
    evt.properties, evt.body)
    │   │           │   └ <member 'body' of '_ConsumerDeliveryEvt' objects>
    │   │           └ <pika.adapters.blocking_connection._ConsumerDeliveryEvt object at 0x7f6498f66e90>
    │   └ <member 'properties' of '_ConsumerDeliveryEvt' objects>
    └ <pika.adapters.blocking_connection._ConsumerDeliveryEvt object at 0x7f6498f66e90>

> File "/home/xh/code/texas_poker/server/network/scheduler.py", line 43, in callback
    self.handle_ai_vs_ai(data)
    │    │               └ {'info': 'ai_vs_ai', 'room_id': 1, 'room_number': 2, 'bots': ['CallAgent', 'CallAgent'], 'game_number': 2, 'uuid': '9854b2b9-...
    │    └ <function Scheduler.handle_ai_vs_ai at 0x7f64995405f0>
    └ <network.scheduler.Scheduler object at 0x7f649b78e410>

  File "/home/xh/code/texas_poker/server/network/scheduler.py", line 64, in handle_ai_vs_ai
    self.notify_bots(room, bots)
    │    │           │     └ ['CallAgent', 'CallAgent']
    │    │           └ {'room_id': 1, 'room_number': 2, 'game_number': 2, 'uuid': [], 'name': [], 'notify_bot': False}
    │    └ <function Scheduler.notify_bots at 0x7f6498f42a70>
    └ <network.scheduler.Scheduler object at 0x7f649b78e410>

  File "/home/xh/code/texas_poker/server/network/scheduler.py", line 97, in notify_bots
    client.connect((cfg["bot"][bot]["host"], cfg["bot"][bot]["port"]))
    │      │        │          │             │          └ 'CallAgent'
    │      │        │          │             └ {'server': {'host': '127.0.0.1', 'port': 12345}, 'bot': {'RandomAgent': {'host': '127.0.0.1', 'port': 20001}, 'CallAgent': {'...
    │      │        │          └ 'CallAgent'
    │      │        └ {'server': {'host': '127.0.0.1', 'port': 12345}, 'bot': {'RandomAgent': {'host': '127.0.0.1', 'port': 20001}, 'CallAgent': {'...
    │      └ <method 'connect' of '_socket.socket' objects>
    └ <socket.socket fd=10, family=AddressFamily.AF_INET, type=SocketKind.SOCK_STREAM, proto=0, laddr=('0.0.0.0', 52778)>

ConnectionRefusedError: [Errno 111] Connection refused
 [*] Waiting for messages. To exit press CTRL+C
Traceback (most recent call last):
  File "init/init_scheduler.py", line 4, in <module>
    Scheduler().start()
  File "/home/xh/code/texas_poker/server/network/scheduler.py", line 109, in start
    self.channel.start_consuming()
  File "/home/xh/anaconda3/envs/platform/lib/python3.7/site-packages/pika/adapters/blocking_connection.py", line 1866, in start_consuming
    self._process_data_events(time_limit=None)
  File "/home/xh/anaconda3/envs/platform/lib/python3.7/site-packages/pika/adapters/blocking_connection.py", line 2027, in _process_data_events
    self.connection.process_data_events(time_limit=time_limit)
  File "/home/xh/anaconda3/envs/platform/lib/python3.7/site-packages/pika/adapters/blocking_connection.py", line 825, in process_data_events
    self._flush_output(common_terminator)
  File "/home/xh/anaconda3/envs/platform/lib/python3.7/site-packages/pika/adapters/blocking_connection.py", line 522, in _flush_output
    raise self._closed_result.value.error
pika.exceptions.ConnectionClosedByBroker: (320, "CONNECTION_FORCED - broker forced connection closure with reason 'shutdown'")
Traceback (most recent call last):
  File "init/init_room_manager.py", line 4, in <module>
    RoomManager().start()
  File "/home/xh/code/texas_poker/server/room/room_manager.py", line 81, in start
    self.channel.start_consuming()
  File "/home/xh/anaconda3/envs/platform/lib/python3.7/site-packages/pika/adapters/blocking_connection.py", line 1866, in start_consuming
    self._process_data_events(time_limit=None)
  File "/home/xh/anaconda3/envs/platform/lib/python3.7/site-packages/pika/adapters/blocking_connection.py", line 2027, in _process_data_events
    self.connection.process_data_events(time_limit=time_limit)
  File "/home/xh/anaconda3/envs/platform/lib/python3.7/site-packages/pika/adapters/blocking_connection.py", line 825, in process_data_events
    self._flush_output(common_terminator)
  File "/home/xh/anaconda3/envs/platform/lib/python3.7/site-packages/pika/adapters/blocking_connection.py", line 522, in _flush_output
    raise self._closed_result.value.error
pika.exceptions.ConnectionClosedByBroker: (320, "CONNECTION_FORCED - broker forced connection closure with reason 'shutdown'")
